DEBUG    botocore.hooks:hooks.py:210 Event before-parameter-build.dynamodb.PutItem: calling handler <function generate_idempotent_uuid at 0x1076ffbf8>
DEBUG    botocore.hooks:hooks.py:210 Event before-parameter-build.dynamodb.PutItem: calling handler <function block_endpoint_discovery_required_operations at 0x1076d4a60>
DEBUG    botocore.hooks:hooks.py:210 Event before-call.dynamodb.PutItem: calling handler <function inject_api_version_header_if_needed at 0x107704620>
DEBUG    botocore.endpoint:endpoint.py:101 Making request for OperationModel(name=PutItem) with params: {'url_path': '/', 'query_string': '', 'method': 'POST', 'headers': {'X-Amz-Target': 'DynamoDB_20120810.PutItem', 'Content-Type': 'application/x-amz-json-1.0', 'User-Agent': 'Boto3/1.9.213 Python/3.7.3 Darwin/18.6.0 Botocore/1.12.213'}, 'body': b'{"TableName": "iot-dynamodb-IotDemoTable-DBSDROSJ2FKQ", "Item": {"date": {"S": "2000-01-01"}, "time": {"S": "06:45:43"}, "location": {"S": "lab-5"}, "source": {"S": "wireless"}, "local_dest": {"S": "router-1"}, "local_avg": {"N": "5.32"}, "remote_dest": {"S": "device-1"}, "remote_avg": {"N": "11.01"}}}', 'url': 'https://dynamodb.us-east-1.amazonaws.com/', 'context': {'client_region': 'us-east-1', 'client_config': <botocore.config.Config object at 0x108449278>, 'has_streaming_input': False, 'auth_type': None}}
DEBUG    botocore.hooks:hooks.py:210 Event request-created.dynamodb.PutItem: calling handler <bound method RequestSigner.handler of <botocore.signers.RequestSigner object at 0x108449240>>
DEBUG    botocore.hooks:hooks.py:210 Event choose-signer.dynamodb.PutItem: calling handler <function set_operation_specific_signer at 0x1076ffae8>
DEBUG    botocore.auth:auth.py:364 Calculating signature using v4 auth.
DEBUG    botocore.auth:auth.py:365 CanonicalRequest:
POST
/

content-type:application/x-amz-json-1.0
host:dynamodb.us-east-1.amazonaws.com
x-amz-date:20190904T164909Z
x-amz-target:DynamoDB_20120810.PutItem

content-type;host;x-amz-date;x-amz-target
f7e44a43d150c8527b020229e6080c6a2fec4e99d61525c9cbee1289cc820b7a
DEBUG    botocore.auth:auth.py:367 StringToSign:
AWS4-HMAC-SHA256
20190904T164909Z
20190904/us-east-1/dynamodb/aws4_request
de0487818908954f0dbd753f1aa3de796fdc70aa4a70f1bb6b09565b663e639b
DEBUG    botocore.auth:auth.py:369 Signature:
5c412158568aba2262cbc49fb3eaf9efe8b0a1b2548c1b562c6f76ab6ef13213
DEBUG    botocore.endpoint:endpoint.py:187 Sending http request: <AWSPreparedRequest stream_output=False, method=POST, url=https://dynamodb.us-east-1.amazonaws.com/, headers={'X-Amz-Target': b'DynamoDB_20120810.PutItem', 'Content-Type': b'application/x-amz-json-1.0', 'User-Agent': b'Boto3/1.9.213 Python/3.7.3 Darwin/18.6.0 Botocore/1.12.213', 'X-Amz-Date': b'20190904T164909Z', 'Authorization': b'AWS4-HMAC-SHA256 Credential=AKIAIOLQ5TSPFGTYHRIA/20190904/us-east-1/dynamodb/aws4_request, SignedHeaders=content-type;host;x-amz-date;x-amz-target, Signature=5c412158568aba2262cbc49fb3eaf9efe8b0a1b2548c1b562c6f76ab6ef13213', 'Content-Length': '303'}>
DEBUG    urllib3.util.retry:retry.py:210 Converted retries value: False -> Retry(total=False, connect=None, read=None, redirect=0, status=None)
DEBUG    urllib3.connectionpool:connectionpool.py:813 Starting new HTTPS connection (1): dynamodb.us-east-1.amazonaws.com:443
DEBUG    botocore.endpoint:endpoint.py:205 Exception received when sending HTTP request.
Traceback (most recent call last):
  File "/usr/local/lib/python3.7/site-packages/urllib3/connection.py", line 159, in _new_conn
    (self._dns_host, self.port), self.timeout, **extra_kw)
  File "/usr/local/lib/python3.7/site-packages/urllib3/util/connection.py", line 57, in create_connection
    for res in socket.getaddrinfo(host, port, family, socket.SOCK_STREAM):
  File "/usr/local/Cellar/python/3.7.3/Frameworks/Python.framework/Versions/3.7/lib/python3.7/socket.py", line 748, in getaddrinfo
    for res in _socket.getaddrinfo(host, port, family, type, proto, flags):
socket.gaierror: [Errno 8] nodename nor servname provided, or not known

During handling of the above exception, another exception occurred:

Traceback (most recent call last):
  File "/usr/local/lib/python3.7/site-packages/botocore/httpsession.py", line 262, in send
    chunked=self._chunked(request.headers),
  File "/usr/local/lib/python3.7/site-packages/urllib3/connectionpool.py", line 638, in urlopen
    _stacktrace=sys.exc_info()[2])
  File "/usr/local/lib/python3.7/site-packages/urllib3/util/retry.py", line 343, in increment
    raise six.reraise(type(error), error, _stacktrace)
  File "/usr/local/lib/python3.7/site-packages/urllib3/packages/six.py", line 686, in reraise
    raise value
  File "/usr/local/lib/python3.7/site-packages/urllib3/connectionpool.py", line 600, in urlopen
    chunked=chunked)
  File "/usr/local/lib/python3.7/site-packages/urllib3/connectionpool.py", line 343, in _make_request
    self._validate_conn(conn)
  File "/usr/local/lib/python3.7/site-packages/urllib3/connectionpool.py", line 839, in _validate_conn
    conn.connect()
  File "/usr/local/lib/python3.7/site-packages/urllib3/connection.py", line 301, in connect
    conn = self._new_conn()
  File "/usr/local/lib/python3.7/site-packages/urllib3/connection.py", line 168, in _new_conn
    self, "Failed to establish a new connection: %s" % e)
urllib3.exceptions.NewConnectionError: <botocore.awsrequest.AWSHTTPSConnection object at 0x1084d0278>: Failed to establish a new connection: [Errno 8] nodename nor servname provided, or not known

During handling of the above exception, another exception occurred:

Traceback (most recent call last):
  File "/usr/local/lib/python3.7/site-packages/botocore/endpoint.py", line 200, in _do_get_response
    http_response = self._send(request)
  File "/usr/local/lib/python3.7/site-packages/botocore/endpoint.py", line 244, in _send
    return self.http_session.send(request)
  File "/usr/local/lib/python3.7/site-packages/botocore/httpsession.py", line 282, in send
    raise EndpointConnectionError(endpoint_url=request.url, error=e)
botocore.exceptions.EndpointConnectionError: Could not connect to the endpoint URL: "https://dynamodb.us-east-1.amazonaws.com/"
DEBUG    botocore.hooks:hooks.py:210 Event needs-retry.dynamodb.PutItem: calling handler <botocore.retryhandler.RetryHandler object at 0x108449630>
DEBUG    botocore.retryhandler:retryhandler.py:272 retry needed, retryable exception caught: Could not connect to the endpoint URL: "https://dynamodb.us-east-1.amazonaws.com/"
Traceback (most recent call last):
  File "/usr/local/lib/python3.7/site-packages/urllib3/connection.py", line 159, in _new_conn
    (self._dns_host, self.port), self.timeout, **extra_kw)
  File "/usr/local/lib/python3.7/site-packages/urllib3/util/connection.py", line 57, in create_connection
    for res in socket.getaddrinfo(host, port, family, socket.SOCK_STREAM):
  File "/usr/local/Cellar/python/3.7.3/Frameworks/Python.framework/Versions/3.7/lib/python3.7/socket.py", line 748, in getaddrinfo
    for res in _socket.getaddrinfo(host, port, family, type, proto, flags):
socket.gaierror: [Errno 8] nodename nor servname provided, or not known

During handling of the above exception, another exception occurred:

Traceback (most recent call last):
  File "/usr/local/lib/python3.7/site-packages/botocore/httpsession.py", line 262, in send
    chunked=self._chunked(request.headers),
  File "/usr/local/lib/python3.7/site-packages/urllib3/connectionpool.py", line 638, in urlopen
    _stacktrace=sys.exc_info()[2])
  File "/usr/local/lib/python3.7/site-packages/urllib3/util/retry.py", line 343, in increment
    raise six.reraise(type(error), error, _stacktrace)
  File "/usr/local/lib/python3.7/site-packages/urllib3/packages/six.py", line 686, in reraise
    raise value
  File "/usr/local/lib/python3.7/site-packages/urllib3/connectionpool.py", line 600, in urlopen
    chunked=chunked)
  File "/usr/local/lib/python3.7/site-packages/urllib3/connectionpool.py", line 343, in _make_request
    self._validate_conn(conn)
  File "/usr/local/lib/python3.7/site-packages/urllib3/connectionpool.py", line 839, in _validate_conn
    conn.connect()
  File "/usr/local/lib/python3.7/site-packages/urllib3/connection.py", line 301, in connect
    conn = self._new_conn()
  File "/usr/local/lib/python3.7/site-packages/urllib3/connection.py", line 168, in _new_conn
    self, "Failed to establish a new connection: %s" % e)
urllib3.exceptions.NewConnectionError: <botocore.awsrequest.AWSHTTPSConnection object at 0x1084d0278>: Failed to establish a new connection: [Errno 8] nodename nor servname provided, or not known

During handling of the above exception, another exception occurred:

Traceback (most recent call last):
  File "/usr/local/lib/python3.7/site-packages/botocore/retryhandler.py", line 269, in _should_retry
    return self._checker(attempt_number, response, caught_exception)
  File "/usr/local/lib/python3.7/site-packages/botocore/retryhandler.py", line 317, in __call__
    caught_exception)
  File "/usr/local/lib/python3.7/site-packages/botocore/retryhandler.py", line 223, in __call__
    attempt_number, caught_exception)
  File "/usr/local/lib/python3.7/site-packages/botocore/retryhandler.py", line 359, in _check_caught_exception
    raise caught_exception
  File "/usr/local/lib/python3.7/site-packages/botocore/endpoint.py", line 200, in _do_get_response
    http_response = self._send(request)
  File "/usr/local/lib/python3.7/site-packages/botocore/endpoint.py", line 244, in _send
    return self.http_session.send(request)
  File "/usr/local/lib/python3.7/site-packages/botocore/httpsession.py", line 282, in send
    raise EndpointConnectionError(endpoint_url=request.url, error=e)
botocore.exceptions.EndpointConnectionError: Could not connect to the endpoint URL: "https://dynamodb.us-east-1.amazonaws.com/"
DEBUG    botocore.retryhandler:retryhandler.py:185 Retry needed, action of: 0.05
DEBUG    botocore.endpoint:endpoint.py:239 Response received to retry, sleeping for 0.05 seconds
DEBUG    botocore.hooks:hooks.py:210 Event request-created.dynamodb.PutItem: calling handler <bound method RequestSigner.handler of <botocore.signers.RequestSigner object at 0x108449240>>
DEBUG    botocore.hooks:hooks.py:210 Event choose-signer.dynamodb.PutItem: calling handler <function set_operation_specific_signer at 0x1076ffae8>
DEBUG    botocore.auth:auth.py:364 Calculating signature using v4 auth.
DEBUG    botocore.auth:auth.py:365 CanonicalRequest:
POST
/

content-type:application/x-amz-json-1.0
host:dynamodb.us-east-1.amazonaws.com
x-amz-date:20190904T164909Z
x-amz-target:DynamoDB_20120810.PutItem

content-type;host;x-amz-date;x-amz-target
f7e44a43d150c8527b020229e6080c6a2fec4e99d61525c9cbee1289cc820b7a
DEBUG    botocore.auth:auth.py:367 StringToSign:
AWS4-HMAC-SHA256
20190904T164909Z
20190904/us-east-1/dynamodb/aws4_request
de0487818908954f0dbd753f1aa3de796fdc70aa4a70f1bb6b09565b663e639b
DEBUG    botocore.auth:auth.py:369 Signature:
5c412158568aba2262cbc49fb3eaf9efe8b0a1b2548c1b562c6f76ab6ef13213
DEBUG    botocore.endpoint:endpoint.py:187 Sending http request: <AWSPreparedRequest stream_output=False, method=POST, url=https://dynamodb.us-east-1.amazonaws.com/, headers={'X-Amz-Target': b'DynamoDB_20120810.PutItem', 'Content-Type': b'application/x-amz-json-1.0', 'User-Agent': b'Boto3/1.9.213 Python/3.7.3 Darwin/18.6.0 Botocore/1.12.213', 'X-Amz-Date': b'20190904T164909Z', 'Authorization': b'AWS4-HMAC-SHA256 Credential=AKIAIOLQ5TSPFGTYHRIA/20190904/us-east-1/dynamodb/aws4_request, SignedHeaders=content-type;host;x-amz-date;x-amz-target, Signature=5c412158568aba2262cbc49fb3eaf9efe8b0a1b2548c1b562c6f76ab6ef13213', 'Content-Length': '303'}>
DEBUG    urllib3.util.retry:retry.py:210 Converted retries value: False -> Retry(total=False, connect=None, read=None, redirect=0, status=None)
DEBUG    urllib3.connectionpool:connectionpool.py:813 Starting new HTTPS connection (2): dynamodb.us-east-1.amazonaws.com:443
DEBUG    botocore.endpoint:endpoint.py:205 Exception received when sending HTTP request.
Traceback (most recent call last):
  File "/usr/local/lib/python3.7/site-packages/urllib3/connection.py", line 159, in _new_conn
    (self._dns_host, self.port), self.timeout, **extra_kw)
  File "/usr/local/lib/python3.7/site-packages/urllib3/util/connection.py", line 57, in create_connection
    for res in socket.getaddrinfo(host, port, family, socket.SOCK_STREAM):
  File "/usr/local/Cellar/python/3.7.3/Frameworks/Python.framework/Versions/3.7/lib/python3.7/socket.py", line 748, in getaddrinfo
    for res in _socket.getaddrinfo(host, port, family, type, proto, flags):
socket.gaierror: [Errno 8] nodename nor servname provided, or not known

During handling of the above exception, another exception occurred:

Traceback (most recent call last):
  File "/usr/local/lib/python3.7/site-packages/botocore/httpsession.py", line 262, in send
    chunked=self._chunked(request.headers),
  File "/usr/local/lib/python3.7/site-packages/urllib3/connectionpool.py", line 638, in urlopen
    _stacktrace=sys.exc_info()[2])
  File "/usr/local/lib/python3.7/site-packages/urllib3/util/retry.py", line 343, in increment
    raise six.reraise(type(error), error, _stacktrace)
  File "/usr/local/lib/python3.7/site-packages/urllib3/packages/six.py", line 686, in reraise
    raise value
  File "/usr/local/lib/python3.7/site-packages/urllib3/connectionpool.py", line 600, in urlopen
    chunked=chunked)
  File "/usr/local/lib/python3.7/site-packages/urllib3/connectionpool.py", line 343, in _make_request
    self._validate_conn(conn)
  File "/usr/local/lib/python3.7/site-packages/urllib3/connectionpool.py", line 839, in _validate_conn
    conn.connect()
  File "/usr/local/lib/python3.7/site-packages/urllib3/connection.py", line 301, in connect
    conn = self._new_conn()
  File "/usr/local/lib/python3.7/site-packages/urllib3/connection.py", line 168, in _new_conn
    self, "Failed to establish a new connection: %s" % e)
urllib3.exceptions.NewConnectionError: <botocore.awsrequest.AWSHTTPSConnection object at 0x10851dd68>: Failed to establish a new connection: [Errno 8] nodename nor servname provided, or not known

During handling of the above exception, another exception occurred:

Traceback (most recent call last):
  File "/usr/local/lib/python3.7/site-packages/botocore/endpoint.py", line 200, in _do_get_response
    http_response = self._send(request)
  File "/usr/local/lib/python3.7/site-packages/botocore/endpoint.py", line 244, in _send
    return self.http_session.send(request)
  File "/usr/local/lib/python3.7/site-packages/botocore/httpsession.py", line 282, in send
    raise EndpointConnectionError(endpoint_url=request.url, error=e)
botocore.exceptions.EndpointConnectionError: Could not connect to the endpoint URL: "https://dynamodb.us-east-1.amazonaws.com/"
DEBUG    botocore.hooks:hooks.py:210 Event needs-retry.dynamodb.PutItem: calling handler <botocore.retryhandler.RetryHandler object at 0x108449630>
DEBUG    botocore.retryhandler:retryhandler.py:272 retry needed, retryable exception caught: Could not connect to the endpoint URL: "https://dynamodb.us-east-1.amazonaws.com/"
Traceback (most recent call last):
  File "/usr/local/lib/python3.7/site-packages/urllib3/connection.py", line 159, in _new_conn
    (self._dns_host, self.port), self.timeout, **extra_kw)
  File "/usr/local/lib/python3.7/site-packages/urllib3/util/connection.py", line 57, in create_connection
    for res in socket.getaddrinfo(host, port, family, socket.SOCK_STREAM):
  File "/usr/local/Cellar/python/3.7.3/Frameworks/Python.framework/Versions/3.7/lib/python3.7/socket.py", line 748, in getaddrinfo
    for res in _socket.getaddrinfo(host, port, family, type, proto, flags):
socket.gaierror: [Errno 8] nodename nor servname provided, or not known

During handling of the above exception, another exception occurred:

Traceback (most recent call last):
  File "/usr/local/lib/python3.7/site-packages/botocore/httpsession.py", line 262, in send
    chunked=self._chunked(request.headers),
  File "/usr/local/lib/python3.7/site-packages/urllib3/connectionpool.py", line 638, in urlopen
    _stacktrace=sys.exc_info()[2])
  File "/usr/local/lib/python3.7/site-packages/urllib3/util/retry.py", line 343, in increment
    raise six.reraise(type(error), error, _stacktrace)
  File "/usr/local/lib/python3.7/site-packages/urllib3/packages/six.py", line 686, in reraise
    raise value
  File "/usr/local/lib/python3.7/site-packages/urllib3/connectionpool.py", line 600, in urlopen
    chunked=chunked)
  File "/usr/local/lib/python3.7/site-packages/urllib3/connectionpool.py", line 343, in _make_request
    self._validate_conn(conn)
  File "/usr/local/lib/python3.7/site-packages/urllib3/connectionpool.py", line 839, in _validate_conn
    conn.connect()
  File "/usr/local/lib/python3.7/site-packages/urllib3/connection.py", line 301, in connect
    conn = self._new_conn()
  File "/usr/local/lib/python3.7/site-packages/urllib3/connection.py", line 168, in _new_conn
    self, "Failed to establish a new connection: %s" % e)
urllib3.exceptions.NewConnectionError: <botocore.awsrequest.AWSHTTPSConnection object at 0x10851dd68>: Failed to establish a new connection: [Errno 8] nodename nor servname provided, or not known

During handling of the above exception, another exception occurred:

Traceback (most recent call last):
  File "/usr/local/lib/python3.7/site-packages/botocore/retryhandler.py", line 269, in _should_retry
    return self._checker(attempt_number, response, caught_exception)
  File "/usr/local/lib/python3.7/site-packages/botocore/retryhandler.py", line 317, in __call__
    caught_exception)
  File "/usr/local/lib/python3.7/site-packages/botocore/retryhandler.py", line 223, in __call__
    attempt_number, caught_exception)
  File "/usr/local/lib/python3.7/site-packages/botocore/retryhandler.py", line 359, in _check_caught_exception
    raise caught_exception
  File "/usr/local/lib/python3.7/site-packages/botocore/endpoint.py", line 200, in _do_get_response
    http_response = self._send(request)
  File "/usr/local/lib/python3.7/site-packages/botocore/endpoint.py", line 244, in _send
    return self.http_session.send(request)
  File "/usr/local/lib/python3.7/site-packages/botocore/httpsession.py", line 282, in send
    raise EndpointConnectionError(endpoint_url=request.url, error=e)
botocore.exceptions.EndpointConnectionError: Could not connect to the endpoint URL: "https://dynamodb.us-east-1.amazonaws.com/"
DEBUG    botocore.retryhandler:retryhandler.py:185 Retry needed, action of: 0.1
DEBUG    botocore.endpoint:endpoint.py:239 Response received to retry, sleeping for 0.1 seconds
DEBUG    botocore.hooks:hooks.py:210 Event request-created.dynamodb.PutItem: calling handler <bound method RequestSigner.handler of <botocore.signers.RequestSigner object at 0x108449240>>
DEBUG    botocore.hooks:hooks.py:210 Event choose-signer.dynamodb.PutItem: calling handler <function set_operation_specific_signer at 0x1076ffae8>
DEBUG    botocore.auth:auth.py:364 Calculating signature using v4 auth.
DEBUG    botocore.auth:auth.py:365 CanonicalRequest:
POST
/

content-type:application/x-amz-json-1.0
host:dynamodb.us-east-1.amazonaws.com
x-amz-date:20190904T164909Z
x-amz-target:DynamoDB_20120810.PutItem

content-type;host;x-amz-date;x-amz-target
f7e44a43d150c8527b020229e6080c6a2fec4e99d61525c9cbee1289cc820b7a
DEBUG    botocore.auth:auth.py:367 StringToSign:
AWS4-HMAC-SHA256
20190904T164909Z
20190904/us-east-1/dynamodb/aws4_request
de0487818908954f0dbd753f1aa3de796fdc70aa4a70f1bb6b09565b663e639b
DEBUG    botocore.auth:auth.py:369 Signature:
5c412158568aba2262cbc49fb3eaf9efe8b0a1b2548c1b562c6f76ab6ef13213
DEBUG    botocore.endpoint:endpoint.py:187 Sending http request: <AWSPreparedRequest stream_output=False, method=POST, url=https://dynamodb.us-east-1.amazonaws.com/, headers={'X-Amz-Target': b'DynamoDB_20120810.PutItem', 'Content-Type': b'application/x-amz-json-1.0', 'User-Agent': b'Boto3/1.9.213 Python/3.7.3 Darwin/18.6.0 Botocore/1.12.213', 'X-Amz-Date': b'20190904T164909Z', 'Authorization': b'AWS4-HMAC-SHA256 Credential=AKIAIOLQ5TSPFGTYHRIA/20190904/us-east-1/dynamodb/aws4_request, SignedHeaders=content-type;host;x-amz-date;x-amz-target, Signature=5c412158568aba2262cbc49fb3eaf9efe8b0a1b2548c1b562c6f76ab6ef13213', 'Content-Length': '303'}>
DEBUG    urllib3.util.retry:retry.py:210 Converted retries value: False -> Retry(total=False, connect=None, read=None, redirect=0, status=None)
DEBUG    urllib3.connectionpool:connectionpool.py:813 Starting new HTTPS connection (3): dynamodb.us-east-1.amazonaws.com:443
DEBUG    botocore.endpoint:endpoint.py:205 Exception received when sending HTTP request.
Traceback (most recent call last):
  File "/usr/local/lib/python3.7/site-packages/urllib3/connection.py", line 159, in _new_conn
    (self._dns_host, self.port), self.timeout, **extra_kw)
  File "/usr/local/lib/python3.7/site-packages/urllib3/util/connection.py", line 57, in create_connection
    for res in socket.getaddrinfo(host, port, family, socket.SOCK_STREAM):
  File "/usr/local/Cellar/python/3.7.3/Frameworks/Python.framework/Versions/3.7/lib/python3.7/socket.py", line 748, in getaddrinfo
    for res in _socket.getaddrinfo(host, port, family, type, proto, flags):
socket.gaierror: [Errno 8] nodename nor servname provided, or not known

During handling of the above exception, another exception occurred:

Traceback (most recent call last):
  File "/usr/local/lib/python3.7/site-packages/botocore/httpsession.py", line 262, in send
    chunked=self._chunked(request.headers),
  File "/usr/local/lib/python3.7/site-packages/urllib3/connectionpool.py", line 638, in urlopen
    _stacktrace=sys.exc_info()[2])
  File "/usr/local/lib/python3.7/site-packages/urllib3/util/retry.py", line 343, in increment
    raise six.reraise(type(error), error, _stacktrace)
  File "/usr/local/lib/python3.7/site-packages/urllib3/packages/six.py", line 686, in reraise
    raise value
  File "/usr/local/lib/python3.7/site-packages/urllib3/connectionpool.py", line 600, in urlopen
    chunked=chunked)
  File "/usr/local/lib/python3.7/site-packages/urllib3/connectionpool.py", line 343, in _make_request
    self._validate_conn(conn)
  File "/usr/local/lib/python3.7/site-packages/urllib3/connectionpool.py", line 839, in _validate_conn
    conn.connect()
  File "/usr/local/lib/python3.7/site-packages/urllib3/connection.py", line 301, in connect
    conn = self._new_conn()
  File "/usr/local/lib/python3.7/site-packages/urllib3/connection.py", line 168, in _new_conn
    self, "Failed to establish a new connection: %s" % e)
urllib3.exceptions.NewConnectionError: <botocore.awsrequest.AWSHTTPSConnection object at 0x1085526a0>: Failed to establish a new connection: [Errno 8] nodename nor servname provided, or not known

During handling of the above exception, another exception occurred:

Traceback (most recent call last):
  File "/usr/local/lib/python3.7/site-packages/botocore/endpoint.py", line 200, in _do_get_response
    http_response = self._send(request)
  File "/usr/local/lib/python3.7/site-packages/botocore/endpoint.py", line 244, in _send
    return self.http_session.send(request)
  File "/usr/local/lib/python3.7/site-packages/botocore/httpsession.py", line 282, in send
    raise EndpointConnectionError(endpoint_url=request.url, error=e)
botocore.exceptions.EndpointConnectionError: Could not connect to the endpoint URL: "https://dynamodb.us-east-1.amazonaws.com/"
DEBUG    botocore.hooks:hooks.py:210 Event needs-retry.dynamodb.PutItem: calling handler <botocore.retryhandler.RetryHandler object at 0x108449630>
DEBUG    botocore.retryhandler:retryhandler.py:272 retry needed, retryable exception caught: Could not connect to the endpoint URL: "https://dynamodb.us-east-1.amazonaws.com/"
Traceback (most recent call last):
  File "/usr/local/lib/python3.7/site-packages/urllib3/connection.py", line 159, in _new_conn
    (self._dns_host, self.port), self.timeout, **extra_kw)
  File "/usr/local/lib/python3.7/site-packages/urllib3/util/connection.py", line 57, in create_connection
    for res in socket.getaddrinfo(host, port, family, socket.SOCK_STREAM):
  File "/usr/local/Cellar/python/3.7.3/Frameworks/Python.framework/Versions/3.7/lib/python3.7/socket.py", line 748, in getaddrinfo
    for res in _socket.getaddrinfo(host, port, family, type, proto, flags):
socket.gaierror: [Errno 8] nodename nor servname provided, or not known

During handling of the above exception, another exception occurred:

Traceback (most recent call last):
  File "/usr/local/lib/python3.7/site-packages/botocore/httpsession.py", line 262, in send
    chunked=self._chunked(request.headers),
  File "/usr/local/lib/python3.7/site-packages/urllib3/connectionpool.py", line 638, in urlopen
    _stacktrace=sys.exc_info()[2])
  File "/usr/local/lib/python3.7/site-packages/urllib3/util/retry.py", line 343, in increment
    raise six.reraise(type(error), error, _stacktrace)
  File "/usr/local/lib/python3.7/site-packages/urllib3/packages/six.py", line 686, in reraise
    raise value
  File "/usr/local/lib/python3.7/site-packages/urllib3/connectionpool.py", line 600, in urlopen
    chunked=chunked)
  File "/usr/local/lib/python3.7/site-packages/urllib3/connectionpool.py", line 343, in _make_request
    self._validate_conn(conn)
  File "/usr/local/lib/python3.7/site-packages/urllib3/connectionpool.py", line 839, in _validate_conn
    conn.connect()
  File "/usr/local/lib/python3.7/site-packages/urllib3/connection.py", line 301, in connect
    conn = self._new_conn()
  File "/usr/local/lib/python3.7/site-packages/urllib3/connection.py", line 168, in _new_conn
    self, "Failed to establish a new connection: %s" % e)
urllib3.exceptions.NewConnectionError: <botocore.awsrequest.AWSHTTPSConnection object at 0x1085526a0>: Failed to establish a new connection: [Errno 8] nodename nor servname provided, or not known

During handling of the above exception, another exception occurred:

Traceback (most recent call last):
  File "/usr/local/lib/python3.7/site-packages/botocore/retryhandler.py", line 269, in _should_retry
    return self._checker(attempt_number, response, caught_exception)
  File "/usr/local/lib/python3.7/site-packages/botocore/retryhandler.py", line 317, in __call__
    caught_exception)
  File "/usr/local/lib/python3.7/site-packages/botocore/retryhandler.py", line 223, in __call__
    attempt_number, caught_exception)
  File "/usr/local/lib/python3.7/site-packages/botocore/retryhandler.py", line 359, in _check_caught_exception
    raise caught_exception
  File "/usr/local/lib/python3.7/site-packages/botocore/endpoint.py", line 200, in _do_get_response
    http_response = self._send(request)
  File "/usr/local/lib/python3.7/site-packages/botocore/endpoint.py", line 244, in _send
    return self.http_session.send(request)
  File "/usr/local/lib/python3.7/site-packages/botocore/httpsession.py", line 282, in send
    raise EndpointConnectionError(endpoint_url=request.url, error=e)
botocore.exceptions.EndpointConnectionError: Could not connect to the endpoint URL: "https://dynamodb.us-east-1.amazonaws.com/"
DEBUG    botocore.retryhandler:retryhandler.py:185 Retry needed, action of: 0.2
DEBUG    botocore.endpoint:endpoint.py:239 Response received to retry, sleeping for 0.2 seconds
DEBUG    botocore.hooks:hooks.py:210 Event request-created.dynamodb.PutItem: calling handler <bound method RequestSigner.handler of <botocore.signers.RequestSigner object at 0x108449240>>
DEBUG    botocore.hooks:hooks.py:210 Event choose-signer.dynamodb.PutItem: calling handler <function set_operation_specific_signer at 0x1076ffae8>
DEBUG    botocore.auth:auth.py:364 Calculating signature using v4 auth.
DEBUG    botocore.auth:auth.py:365 CanonicalRequest:
POST
/

content-type:application/x-amz-json-1.0
host:dynamodb.us-east-1.amazonaws.com
x-amz-date:20190904T164909Z
x-amz-target:DynamoDB_20120810.PutItem

content-type;host;x-amz-date;x-amz-target
f7e44a43d150c8527b020229e6080c6a2fec4e99d61525c9cbee1289cc820b7a
DEBUG    botocore.auth:auth.py:367 StringToSign:
AWS4-HMAC-SHA256
20190904T164909Z
20190904/us-east-1/dynamodb/aws4_request
de0487818908954f0dbd753f1aa3de796fdc70aa4a70f1bb6b09565b663e639b
DEBUG    botocore.auth:auth.py:369 Signature:
5c412158568aba2262cbc49fb3eaf9efe8b0a1b2548c1b562c6f76ab6ef13213
DEBUG    botocore.endpoint:endpoint.py:187 Sending http request: <AWSPreparedRequest stream_output=False, method=POST, url=https://dynamodb.us-east-1.amazonaws.com/, headers={'X-Amz-Target': b'DynamoDB_20120810.PutItem', 'Content-Type': b'application/x-amz-json-1.0', 'User-Agent': b'Boto3/1.9.213 Python/3.7.3 Darwin/18.6.0 Botocore/1.12.213', 'X-Amz-Date': b'20190904T164909Z', 'Authorization': b'AWS4-HMAC-SHA256 Credential=AKIAIOLQ5TSPFGTYHRIA/20190904/us-east-1/dynamodb/aws4_request, SignedHeaders=content-type;host;x-amz-date;x-amz-target, Signature=5c412158568aba2262cbc49fb3eaf9efe8b0a1b2548c1b562c6f76ab6ef13213', 'Content-Length': '303'}>
DEBUG    urllib3.util.retry:retry.py:210 Converted retries value: False -> Retry(total=False, connect=None, read=None, redirect=0, status=None)
DEBUG    urllib3.connectionpool:connectionpool.py:813 Starting new HTTPS connection (4): dynamodb.us-east-1.amazonaws.com:443
DEBUG    botocore.endpoint:endpoint.py:205 Exception received when sending HTTP request.
Traceback (most recent call last):
  File "/usr/local/lib/python3.7/site-packages/urllib3/connection.py", line 159, in _new_conn
    (self._dns_host, self.port), self.timeout, **extra_kw)
  File "/usr/local/lib/python3.7/site-packages/urllib3/util/connection.py", line 57, in create_connection
    for res in socket.getaddrinfo(host, port, family, socket.SOCK_STREAM):
  File "/usr/local/Cellar/python/3.7.3/Frameworks/Python.framework/Versions/3.7/lib/python3.7/socket.py", line 748, in getaddrinfo
    for res in _socket.getaddrinfo(host, port, family, type, proto, flags):
socket.gaierror: [Errno 8] nodename nor servname provided, or not known

During handling of the above exception, another exception occurred:

Traceback (most recent call last):
  File "/usr/local/lib/python3.7/site-packages/botocore/httpsession.py", line 262, in send
    chunked=self._chunked(request.headers),
  File "/usr/local/lib/python3.7/site-packages/urllib3/connectionpool.py", line 638, in urlopen
    _stacktrace=sys.exc_info()[2])
  File "/usr/local/lib/python3.7/site-packages/urllib3/util/retry.py", line 343, in increment
    raise six.reraise(type(error), error, _stacktrace)
  File "/usr/local/lib/python3.7/site-packages/urllib3/packages/six.py", line 686, in reraise
    raise value
  File "/usr/local/lib/python3.7/site-packages/urllib3/connectionpool.py", line 600, in urlopen
    chunked=chunked)
  File "/usr/local/lib/python3.7/site-packages/urllib3/connectionpool.py", line 343, in _make_request
    self._validate_conn(conn)
  File "/usr/local/lib/python3.7/site-packages/urllib3/connectionpool.py", line 839, in _validate_conn
    conn.connect()
  File "/usr/local/lib/python3.7/site-packages/urllib3/connection.py", line 301, in connect
    conn = self._new_conn()
  File "/usr/local/lib/python3.7/site-packages/urllib3/connection.py", line 168, in _new_conn
    self, "Failed to establish a new connection: %s" % e)
urllib3.exceptions.NewConnectionError: <botocore.awsrequest.AWSHTTPSConnection object at 0x10855a048>: Failed to establish a new connection: [Errno 8] nodename nor servname provided, or not known

During handling of the above exception, another exception occurred:

Traceback (most recent call last):
  File "/usr/local/lib/python3.7/site-packages/botocore/endpoint.py", line 200, in _do_get_response
    http_response = self._send(request)
  File "/usr/local/lib/python3.7/site-packages/botocore/endpoint.py", line 244, in _send
    return self.http_session.send(request)
  File "/usr/local/lib/python3.7/site-packages/botocore/httpsession.py", line 282, in send
    raise EndpointConnectionError(endpoint_url=request.url, error=e)
botocore.exceptions.EndpointConnectionError: Could not connect to the endpoint URL: "https://dynamodb.us-east-1.amazonaws.com/"
DEBUG    botocore.hooks:hooks.py:210 Event needs-retry.dynamodb.PutItem: calling handler <botocore.retryhandler.RetryHandler object at 0x108449630>
DEBUG    botocore.retryhandler:retryhandler.py:272 retry needed, retryable exception caught: Could not connect to the endpoint URL: "https://dynamodb.us-east-1.amazonaws.com/"
Traceback (most recent call last):
  File "/usr/local/lib/python3.7/site-packages/urllib3/connection.py", line 159, in _new_conn
    (self._dns_host, self.port), self.timeout, **extra_kw)
  File "/usr/local/lib/python3.7/site-packages/urllib3/util/connection.py", line 57, in create_connection
    for res in socket.getaddrinfo(host, port, family, socket.SOCK_STREAM):
  File "/usr/local/Cellar/python/3.7.3/Frameworks/Python.framework/Versions/3.7/lib/python3.7/socket.py", line 748, in getaddrinfo
    for res in _socket.getaddrinfo(host, port, family, type, proto, flags):
socket.gaierror: [Errno 8] nodename nor servname provided, or not known

During handling of the above exception, another exception occurred:

Traceback (most recent call last):
  File "/usr/local/lib/python3.7/site-packages/botocore/httpsession.py", line 262, in send
    chunked=self._chunked(request.headers),
  File "/usr/local/lib/python3.7/site-packages/urllib3/connectionpool.py", line 638, in urlopen
    _stacktrace=sys.exc_info()[2])
  File "/usr/local/lib/python3.7/site-packages/urllib3/util/retry.py", line 343, in increment
    raise six.reraise(type(error), error, _stacktrace)
  File "/usr/local/lib/python3.7/site-packages/urllib3/packages/six.py", line 686, in reraise
    raise value
  File "/usr/local/lib/python3.7/site-packages/urllib3/connectionpool.py", line 600, in urlopen
    chunked=chunked)
  File "/usr/local/lib/python3.7/site-packages/urllib3/connectionpool.py", line 343, in _make_request
    self._validate_conn(conn)
  File "/usr/local/lib/python3.7/site-packages/urllib3/connectionpool.py", line 839, in _validate_conn
    conn.connect()
  File "/usr/local/lib/python3.7/site-packages/urllib3/connection.py", line 301, in connect
    conn = self._new_conn()
  File "/usr/local/lib/python3.7/site-packages/urllib3/connection.py", line 168, in _new_conn
    self, "Failed to establish a new connection: %s" % e)
urllib3.exceptions.NewConnectionError: <botocore.awsrequest.AWSHTTPSConnection object at 0x10855a048>: Failed to establish a new connection: [Errno 8] nodename nor servname provided, or not known

During handling of the above exception, another exception occurred:

Traceback (most recent call last):
  File "/usr/local/lib/python3.7/site-packages/botocore/retryhandler.py", line 269, in _should_retry
    return self._checker(attempt_number, response, caught_exception)
  File "/usr/local/lib/python3.7/site-packages/botocore/retryhandler.py", line 317, in __call__
    caught_exception)
  File "/usr/local/lib/python3.7/site-packages/botocore/retryhandler.py", line 223, in __call__
    attempt_number, caught_exception)
  File "/usr/local/lib/python3.7/site-packages/botocore/retryhandler.py", line 359, in _check_caught_exception
    raise caught_exception
  File "/usr/local/lib/python3.7/site-packages/botocore/endpoint.py", line 200, in _do_get_response
    http_response = self._send(request)
  File "/usr/local/lib/python3.7/site-packages/botocore/endpoint.py", line 244, in _send
    return self.http_session.send(request)
  File "/usr/local/lib/python3.7/site-packages/botocore/httpsession.py", line 282, in send
    raise EndpointConnectionError(endpoint_url=request.url, error=e)
botocore.exceptions.EndpointConnectionError: Could not connect to the endpoint URL: "https://dynamodb.us-east-1.amazonaws.com/"
DEBUG    botocore.retryhandler:retryhandler.py:185 Retry needed, action of: 0.4
DEBUG    botocore.endpoint:endpoint.py:239 Response received to retry, sleeping for 0.4 seconds
DEBUG    botocore.hooks:hooks.py:210 Event request-created.dynamodb.PutItem: calling handler <bound method RequestSigner.handler of <botocore.signers.RequestSigner object at 0x108449240>>
DEBUG    botocore.hooks:hooks.py:210 Event choose-signer.dynamodb.PutItem: calling handler <function set_operation_specific_signer at 0x1076ffae8>
DEBUG    botocore.auth:auth.py:364 Calculating signature using v4 auth.
DEBUG    botocore.auth:auth.py:365 CanonicalRequest:
POST
/

content-type:application/x-amz-json-1.0
host:dynamodb.us-east-1.amazonaws.com
x-amz-date:20190904T164910Z
x-amz-target:DynamoDB_20120810.PutItem

content-type;host;x-amz-date;x-amz-target
f7e44a43d150c8527b020229e6080c6a2fec4e99d61525c9cbee1289cc820b7a
DEBUG    botocore.auth:auth.py:367 StringToSign:
AWS4-HMAC-SHA256
20190904T164910Z
20190904/us-east-1/dynamodb/aws4_request
5f61b2fa4d253d720415cccdb3a02af8779c5de927bbbf3f0266af46a291bd42
DEBUG    botocore.auth:auth.py:369 Signature:
91d6711fa82dadbecb82be6307fdf2d5c8923dccfa17334f59d08176b15e1aeb
DEBUG    botocore.endpoint:endpoint.py:187 Sending http request: <AWSPreparedRequest stream_output=False, method=POST, url=https://dynamodb.us-east-1.amazonaws.com/, headers={'X-Amz-Target': b'DynamoDB_20120810.PutItem', 'Content-Type': b'application/x-amz-json-1.0', 'User-Agent': b'Boto3/1.9.213 Python/3.7.3 Darwin/18.6.0 Botocore/1.12.213', 'X-Amz-Date': b'20190904T164910Z', 'Authorization': b'AWS4-HMAC-SHA256 Credential=AKIAIOLQ5TSPFGTYHRIA/20190904/us-east-1/dynamodb/aws4_request, SignedHeaders=content-type;host;x-amz-date;x-amz-target, Signature=91d6711fa82dadbecb82be6307fdf2d5c8923dccfa17334f59d08176b15e1aeb', 'Content-Length': '303'}>
DEBUG    urllib3.util.retry:retry.py:210 Converted retries value: False -> Retry(total=False, connect=None, read=None, redirect=0, status=None)
DEBUG    urllib3.connectionpool:connectionpool.py:813 Starting new HTTPS connection (5): dynamodb.us-east-1.amazonaws.com:443
DEBUG    botocore.endpoint:endpoint.py:205 Exception received when sending HTTP request.
Traceback (most recent call last):
  File "/usr/local/lib/python3.7/site-packages/urllib3/connection.py", line 159, in _new_conn
    (self._dns_host, self.port), self.timeout, **extra_kw)
  File "/usr/local/lib/python3.7/site-packages/urllib3/util/connection.py", line 57, in create_connection
    for res in socket.getaddrinfo(host, port, family, socket.SOCK_STREAM):
  File "/usr/local/Cellar/python/3.7.3/Frameworks/Python.framework/Versions/3.7/lib/python3.7/socket.py", line 748, in getaddrinfo
    for res in _socket.getaddrinfo(host, port, family, type, proto, flags):
socket.gaierror: [Errno 8] nodename nor servname provided, or not known

During handling of the above exception, another exception occurred:

Traceback (most recent call last):
  File "/usr/local/lib/python3.7/site-packages/botocore/httpsession.py", line 262, in send
    chunked=self._chunked(request.headers),
  File "/usr/local/lib/python3.7/site-packages/urllib3/connectionpool.py", line 638, in urlopen
    _stacktrace=sys.exc_info()[2])
  File "/usr/local/lib/python3.7/site-packages/urllib3/util/retry.py", line 343, in increment
    raise six.reraise(type(error), error, _stacktrace)
  File "/usr/local/lib/python3.7/site-packages/urllib3/packages/six.py", line 686, in reraise
    raise value
  File "/usr/local/lib/python3.7/site-packages/urllib3/connectionpool.py", line 600, in urlopen
    chunked=chunked)
  File "/usr/local/lib/python3.7/site-packages/urllib3/connectionpool.py", line 343, in _make_request
    self._validate_conn(conn)
  File "/usr/local/lib/python3.7/site-packages/urllib3/connectionpool.py", line 839, in _validate_conn
    conn.connect()
  File "/usr/local/lib/python3.7/site-packages/urllib3/connection.py", line 301, in connect
    conn = self._new_conn()
  File "/usr/local/lib/python3.7/site-packages/urllib3/connection.py", line 168, in _new_conn
    self, "Failed to establish a new connection: %s" % e)
urllib3.exceptions.NewConnectionError: <botocore.awsrequest.AWSHTTPSConnection object at 0x10855ab00>: Failed to establish a new connection: [Errno 8] nodename nor servname provided, or not known

During handling of the above exception, another exception occurred:

Traceback (most recent call last):
  File "/usr/local/lib/python3.7/site-packages/botocore/endpoint.py", line 200, in _do_get_response
    http_response = self._send(request)
  File "/usr/local/lib/python3.7/site-packages/botocore/endpoint.py", line 244, in _send
    return self.http_session.send(request)
  File "/usr/local/lib/python3.7/site-packages/botocore/httpsession.py", line 282, in send
    raise EndpointConnectionError(endpoint_url=request.url, error=e)
botocore.exceptions.EndpointConnectionError: Could not connect to the endpoint URL: "https://dynamodb.us-east-1.amazonaws.com/"
DEBUG    botocore.hooks:hooks.py:210 Event needs-retry.dynamodb.PutItem: calling handler <botocore.retryhandler.RetryHandler object at 0x108449630>
DEBUG    botocore.retryhandler:retryhandler.py:272 retry needed, retryable exception caught: Could not connect to the endpoint URL: "https://dynamodb.us-east-1.amazonaws.com/"
Traceback (most recent call last):
  File "/usr/local/lib/python3.7/site-packages/urllib3/connection.py", line 159, in _new_conn
    (self._dns_host, self.port), self.timeout, **extra_kw)
  File "/usr/local/lib/python3.7/site-packages/urllib3/util/connection.py", line 57, in create_connection
    for res in socket.getaddrinfo(host, port, family, socket.SOCK_STREAM):
  File "/usr/local/Cellar/python/3.7.3/Frameworks/Python.framework/Versions/3.7/lib/python3.7/socket.py", line 748, in getaddrinfo
    for res in _socket.getaddrinfo(host, port, family, type, proto, flags):
socket.gaierror: [Errno 8] nodename nor servname provided, or not known

During handling of the above exception, another exception occurred:

Traceback (most recent call last):
  File "/usr/local/lib/python3.7/site-packages/botocore/httpsession.py", line 262, in send
    chunked=self._chunked(request.headers),
  File "/usr/local/lib/python3.7/site-packages/urllib3/connectionpool.py", line 638, in urlopen
    _stacktrace=sys.exc_info()[2])
  File "/usr/local/lib/python3.7/site-packages/urllib3/util/retry.py", line 343, in increment
    raise six.reraise(type(error), error, _stacktrace)
  File "/usr/local/lib/python3.7/site-packages/urllib3/packages/six.py", line 686, in reraise
    raise value
  File "/usr/local/lib/python3.7/site-packages/urllib3/connectionpool.py", line 600, in urlopen
    chunked=chunked)
  File "/usr/local/lib/python3.7/site-packages/urllib3/connectionpool.py", line 343, in _make_request
    self._validate_conn(conn)
  File "/usr/local/lib/python3.7/site-packages/urllib3/connectionpool.py", line 839, in _validate_conn
    conn.connect()
  File "/usr/local/lib/python3.7/site-packages/urllib3/connection.py", line 301, in connect
    conn = self._new_conn()
  File "/usr/local/lib/python3.7/site-packages/urllib3/connection.py", line 168, in _new_conn
    self, "Failed to establish a new connection: %s" % e)
urllib3.exceptions.NewConnectionError: <botocore.awsrequest.AWSHTTPSConnection object at 0x10855ab00>: Failed to establish a new connection: [Errno 8] nodename nor servname provided, or not known

During handling of the above exception, another exception occurred:

Traceback (most recent call last):
  File "/usr/local/lib/python3.7/site-packages/botocore/retryhandler.py", line 269, in _should_retry
    return self._checker(attempt_number, response, caught_exception)
  File "/usr/local/lib/python3.7/site-packages/botocore/retryhandler.py", line 317, in __call__
    caught_exception)
  File "/usr/local/lib/python3.7/site-packages/botocore/retryhandler.py", line 223, in __call__
    attempt_number, caught_exception)
  File "/usr/local/lib/python3.7/site-packages/botocore/retryhandler.py", line 359, in _check_caught_exception
    raise caught_exception
  File "/usr/local/lib/python3.7/site-packages/botocore/endpoint.py", line 200, in _do_get_response
    http_response = self._send(request)
  File "/usr/local/lib/python3.7/site-packages/botocore/endpoint.py", line 244, in _send
    return self.http_session.send(request)
  File "/usr/local/lib/python3.7/site-packages/botocore/httpsession.py", line 282, in send
    raise EndpointConnectionError(endpoint_url=request.url, error=e)
botocore.exceptions.EndpointConnectionError: Could not connect to the endpoint URL: "https://dynamodb.us-east-1.amazonaws.com/"
DEBUG    botocore.retryhandler:retryhandler.py:185 Retry needed, action of: 0.8
DEBUG    botocore.endpoint:endpoint.py:239 Response received to retry, sleeping for 0.8 seconds
DEBUG    botocore.hooks:hooks.py:210 Event request-created.dynamodb.PutItem: calling handler <bound method RequestSigner.handler of <botocore.signers.RequestSigner object at 0x108449240>>
DEBUG    botocore.hooks:hooks.py:210 Event choose-signer.dynamodb.PutItem: calling handler <function set_operation_specific_signer at 0x1076ffae8>
DEBUG    botocore.auth:auth.py:364 Calculating signature using v4 auth.
DEBUG    botocore.auth:auth.py:365 CanonicalRequest:
POST
/

content-type:application/x-amz-json-1.0
host:dynamodb.us-east-1.amazonaws.com
x-amz-date:20190904T164910Z
x-amz-target:DynamoDB_20120810.PutItem

content-type;host;x-amz-date;x-amz-target
f7e44a43d150c8527b020229e6080c6a2fec4e99d61525c9cbee1289cc820b7a
DEBUG    botocore.auth:auth.py:367 StringToSign:
AWS4-HMAC-SHA256
20190904T164910Z
20190904/us-east-1/dynamodb/aws4_request
5f61b2fa4d253d720415cccdb3a02af8779c5de927bbbf3f0266af46a291bd42
DEBUG    botocore.auth:auth.py:369 Signature:
91d6711fa82dadbecb82be6307fdf2d5c8923dccfa17334f59d08176b15e1aeb
DEBUG    botocore.endpoint:endpoint.py:187 Sending http request: <AWSPreparedRequest stream_output=False, method=POST, url=https://dynamodb.us-east-1.amazonaws.com/, headers={'X-Amz-Target': b'DynamoDB_20120810.PutItem', 'Content-Type': b'application/x-amz-json-1.0', 'User-Agent': b'Boto3/1.9.213 Python/3.7.3 Darwin/18.6.0 Botocore/1.12.213', 'X-Amz-Date': b'20190904T164910Z', 'Authorization': b'AWS4-HMAC-SHA256 Credential=AKIAIOLQ5TSPFGTYHRIA/20190904/us-east-1/dynamodb/aws4_request, SignedHeaders=content-type;host;x-amz-date;x-amz-target, Signature=91d6711fa82dadbecb82be6307fdf2d5c8923dccfa17334f59d08176b15e1aeb', 'Content-Length': '303'}>
DEBUG    urllib3.util.retry:retry.py:210 Converted retries value: False -> Retry(total=False, connect=None, read=None, redirect=0, status=None)
DEBUG    urllib3.connectionpool:connectionpool.py:813 Starting new HTTPS connection (6): dynamodb.us-east-1.amazonaws.com:443
DEBUG    botocore.endpoint:endpoint.py:205 Exception received when sending HTTP request.
Traceback (most recent call last):
  File "/usr/local/lib/python3.7/site-packages/urllib3/connection.py", line 159, in _new_conn
    (self._dns_host, self.port), self.timeout, **extra_kw)
  File "/usr/local/lib/python3.7/site-packages/urllib3/util/connection.py", line 57, in create_connection
    for res in socket.getaddrinfo(host, port, family, socket.SOCK_STREAM):
  File "/usr/local/Cellar/python/3.7.3/Frameworks/Python.framework/Versions/3.7/lib/python3.7/socket.py", line 748, in getaddrinfo
    for res in _socket.getaddrinfo(host, port, family, type, proto, flags):
socket.gaierror: [Errno 8] nodename nor servname provided, or not known

During handling of the above exception, another exception occurred:

Traceback (most recent call last):
  File "/usr/local/lib/python3.7/site-packages/botocore/httpsession.py", line 262, in send
    chunked=self._chunked(request.headers),
  File "/usr/local/lib/python3.7/site-packages/urllib3/connectionpool.py", line 638, in urlopen
    _stacktrace=sys.exc_info()[2])
  File "/usr/local/lib/python3.7/site-packages/urllib3/util/retry.py", line 343, in increment
    raise six.reraise(type(error), error, _stacktrace)
  File "/usr/local/lib/python3.7/site-packages/urllib3/packages/six.py", line 686, in reraise
    raise value
  File "/usr/local/lib/python3.7/site-packages/urllib3/connectionpool.py", line 600, in urlopen
    chunked=chunked)
  File "/usr/local/lib/python3.7/site-packages/urllib3/connectionpool.py", line 343, in _make_request
    self._validate_conn(conn)
  File "/usr/local/lib/python3.7/site-packages/urllib3/connectionpool.py", line 839, in _validate_conn
    conn.connect()
  File "/usr/local/lib/python3.7/site-packages/urllib3/connection.py", line 301, in connect
    conn = self._new_conn()
  File "/usr/local/lib/python3.7/site-packages/urllib3/connection.py", line 168, in _new_conn
    self, "Failed to establish a new connection: %s" % e)
urllib3.exceptions.NewConnectionError: <botocore.awsrequest.AWSHTTPSConnection object at 0x1085655f8>: Failed to establish a new connection: [Errno 8] nodename nor servname provided, or not known

During handling of the above exception, another exception occurred:

Traceback (most recent call last):
  File "/usr/local/lib/python3.7/site-packages/botocore/endpoint.py", line 200, in _do_get_response
    http_response = self._send(request)
  File "/usr/local/lib/python3.7/site-packages/botocore/endpoint.py", line 244, in _send
    return self.http_session.send(request)
  File "/usr/local/lib/python3.7/site-packages/botocore/httpsession.py", line 282, in send
    raise EndpointConnectionError(endpoint_url=request.url, error=e)
botocore.exceptions.EndpointConnectionError: Could not connect to the endpoint URL: "https://dynamodb.us-east-1.amazonaws.com/"
DEBUG    botocore.hooks:hooks.py:210 Event needs-retry.dynamodb.PutItem: calling handler <botocore.retryhandler.RetryHandler object at 0x108449630>
DEBUG    botocore.retryhandler:retryhandler.py:272 retry needed, retryable exception caught: Could not connect to the endpoint URL: "https://dynamodb.us-east-1.amazonaws.com/"
Traceback (most recent call last):
  File "/usr/local/lib/python3.7/site-packages/urllib3/connection.py", line 159, in _new_conn
    (self._dns_host, self.port), self.timeout, **extra_kw)
  File "/usr/local/lib/python3.7/site-packages/urllib3/util/connection.py", line 57, in create_connection
    for res in socket.getaddrinfo(host, port, family, socket.SOCK_STREAM):
  File "/usr/local/Cellar/python/3.7.3/Frameworks/Python.framework/Versions/3.7/lib/python3.7/socket.py", line 748, in getaddrinfo
    for res in _socket.getaddrinfo(host, port, family, type, proto, flags):
socket.gaierror: [Errno 8] nodename nor servname provided, or not known

During handling of the above exception, another exception occurred:

Traceback (most recent call last):
  File "/usr/local/lib/python3.7/site-packages/botocore/httpsession.py", line 262, in send
    chunked=self._chunked(request.headers),
  File "/usr/local/lib/python3.7/site-packages/urllib3/connectionpool.py", line 638, in urlopen
    _stacktrace=sys.exc_info()[2])
  File "/usr/local/lib/python3.7/site-packages/urllib3/util/retry.py", line 343, in increment
    raise six.reraise(type(error), error, _stacktrace)
  File "/usr/local/lib/python3.7/site-packages/urllib3/packages/six.py", line 686, in reraise
    raise value
  File "/usr/local/lib/python3.7/site-packages/urllib3/connectionpool.py", line 600, in urlopen
    chunked=chunked)
  File "/usr/local/lib/python3.7/site-packages/urllib3/connectionpool.py", line 343, in _make_request
    self._validate_conn(conn)
  File "/usr/local/lib/python3.7/site-packages/urllib3/connectionpool.py", line 839, in _validate_conn
    conn.connect()
  File "/usr/local/lib/python3.7/site-packages/urllib3/connection.py", line 301, in connect
    conn = self._new_conn()
  File "/usr/local/lib/python3.7/site-packages/urllib3/connection.py", line 168, in _new_conn
    self, "Failed to establish a new connection: %s" % e)
urllib3.exceptions.NewConnectionError: <botocore.awsrequest.AWSHTTPSConnection object at 0x1085655f8>: Failed to establish a new connection: [Errno 8] nodename nor servname provided, or not known

During handling of the above exception, another exception occurred:

Traceback (most recent call last):
  File "/usr/local/lib/python3.7/site-packages/botocore/retryhandler.py", line 269, in _should_retry
    return self._checker(attempt_number, response, caught_exception)
  File "/usr/local/lib/python3.7/site-packages/botocore/retryhandler.py", line 317, in __call__
    caught_exception)
  File "/usr/local/lib/python3.7/site-packages/botocore/retryhandler.py", line 223, in __call__
    attempt_number, caught_exception)
  File "/usr/local/lib/python3.7/site-packages/botocore/retryhandler.py", line 359, in _check_caught_exception
    raise caught_exception
  File "/usr/local/lib/python3.7/site-packages/botocore/endpoint.py", line 200, in _do_get_response
    http_response = self._send(request)
  File "/usr/local/lib/python3.7/site-packages/botocore/endpoint.py", line 244, in _send
    return self.http_session.send(request)
  File "/usr/local/lib/python3.7/site-packages/botocore/httpsession.py", line 282, in send
    raise EndpointConnectionError(endpoint_url=request.url, error=e)
botocore.exceptions.EndpointConnectionError: Could not connect to the endpoint URL: "https://dynamodb.us-east-1.amazonaws.com/"
DEBUG    botocore.retryhandler:retryhandler.py:185 Retry needed, action of: 1.6
DEBUG    botocore.endpoint:endpoint.py:239 Response received to retry, sleeping for 1.6 seconds
DEBUG    botocore.hooks:hooks.py:210 Event request-created.dynamodb.PutItem: calling handler <bound method RequestSigner.handler of <botocore.signers.RequestSigner object at 0x108449240>>
DEBUG    botocore.hooks:hooks.py:210 Event choose-signer.dynamodb.PutItem: calling handler <function set_operation_specific_signer at 0x1076ffae8>
DEBUG    botocore.auth:auth.py:364 Calculating signature using v4 auth.
DEBUG    botocore.auth:auth.py:365 CanonicalRequest:
POST
/

content-type:application/x-amz-json-1.0
host:dynamodb.us-east-1.amazonaws.com
x-amz-date:20190904T164912Z
x-amz-target:DynamoDB_20120810.PutItem

content-type;host;x-amz-date;x-amz-target
f7e44a43d150c8527b020229e6080c6a2fec4e99d61525c9cbee1289cc820b7a
DEBUG    botocore.auth:auth.py:367 StringToSign:
AWS4-HMAC-SHA256
20190904T164912Z
20190904/us-east-1/dynamodb/aws4_request
364da9dcf43e936088ba52b37c47064493ca98c440ca97bb8cbd2dd0e4a34421
DEBUG    botocore.auth:auth.py:369 Signature:
9d3a6f67c95232356050fad260b41e8351ce6df7b9cb83d5c36cb38852938b12
DEBUG    botocore.endpoint:endpoint.py:187 Sending http request: <AWSPreparedRequest stream_output=False, method=POST, url=https://dynamodb.us-east-1.amazonaws.com/, headers={'X-Amz-Target': b'DynamoDB_20120810.PutItem', 'Content-Type': b'application/x-amz-json-1.0', 'User-Agent': b'Boto3/1.9.213 Python/3.7.3 Darwin/18.6.0 Botocore/1.12.213', 'X-Amz-Date': b'20190904T164912Z', 'Authorization': b'AWS4-HMAC-SHA256 Credential=AKIAIOLQ5TSPFGTYHRIA/20190904/us-east-1/dynamodb/aws4_request, SignedHeaders=content-type;host;x-amz-date;x-amz-target, Signature=9d3a6f67c95232356050fad260b41e8351ce6df7b9cb83d5c36cb38852938b12', 'Content-Length': '303'}>
DEBUG    urllib3.util.retry:retry.py:210 Converted retries value: False -> Retry(total=False, connect=None, read=None, redirect=0, status=None)
DEBUG    urllib3.connectionpool:connectionpool.py:813 Starting new HTTPS connection (7): dynamodb.us-east-1.amazonaws.com:443
DEBUG    botocore.endpoint:endpoint.py:205 Exception received when sending HTTP request.
Traceback (most recent call last):
  File "/usr/local/lib/python3.7/site-packages/urllib3/connection.py", line 159, in _new_conn
    (self._dns_host, self.port), self.timeout, **extra_kw)
  File "/usr/local/lib/python3.7/site-packages/urllib3/util/connection.py", line 57, in create_connection
    for res in socket.getaddrinfo(host, port, family, socket.SOCK_STREAM):
  File "/usr/local/Cellar/python/3.7.3/Frameworks/Python.framework/Versions/3.7/lib/python3.7/socket.py", line 748, in getaddrinfo
    for res in _socket.getaddrinfo(host, port, family, type, proto, flags):
socket.gaierror: [Errno 8] nodename nor servname provided, or not known

During handling of the above exception, another exception occurred:

Traceback (most recent call last):
  File "/usr/local/lib/python3.7/site-packages/botocore/httpsession.py", line 262, in send
    chunked=self._chunked(request.headers),
  File "/usr/local/lib/python3.7/site-packages/urllib3/connectionpool.py", line 638, in urlopen
    _stacktrace=sys.exc_info()[2])
  File "/usr/local/lib/python3.7/site-packages/urllib3/util/retry.py", line 343, in increment
    raise six.reraise(type(error), error, _stacktrace)
  File "/usr/local/lib/python3.7/site-packages/urllib3/packages/six.py", line 686, in reraise
    raise value
  File "/usr/local/lib/python3.7/site-packages/urllib3/connectionpool.py", line 600, in urlopen
    chunked=chunked)
  File "/usr/local/lib/python3.7/site-packages/urllib3/connectionpool.py", line 343, in _make_request
    self._validate_conn(conn)
  File "/usr/local/lib/python3.7/site-packages/urllib3/connectionpool.py", line 839, in _validate_conn
    conn.connect()
  File "/usr/local/lib/python3.7/site-packages/urllib3/connection.py", line 301, in connect
    conn = self._new_conn()
  File "/usr/local/lib/python3.7/site-packages/urllib3/connection.py", line 168, in _new_conn
    self, "Failed to establish a new connection: %s" % e)
urllib3.exceptions.NewConnectionError: <botocore.awsrequest.AWSHTTPSConnection object at 0x10856b0f0>: Failed to establish a new connection: [Errno 8] nodename nor servname provided, or not known

During handling of the above exception, another exception occurred:

Traceback (most recent call last):
  File "/usr/local/lib/python3.7/site-packages/botocore/endpoint.py", line 200, in _do_get_response
    http_response = self._send(request)
  File "/usr/local/lib/python3.7/site-packages/botocore/endpoint.py", line 244, in _send
    return self.http_session.send(request)
  File "/usr/local/lib/python3.7/site-packages/botocore/httpsession.py", line 282, in send
    raise EndpointConnectionError(endpoint_url=request.url, error=e)
botocore.exceptions.EndpointConnectionError: Could not connect to the endpoint URL: "https://dynamodb.us-east-1.amazonaws.com/"
DEBUG    botocore.hooks:hooks.py:210 Event needs-retry.dynamodb.PutItem: calling handler <botocore.retryhandler.RetryHandler object at 0x108449630>
DEBUG    botocore.retryhandler:retryhandler.py:272 retry needed, retryable exception caught: Could not connect to the endpoint URL: "https://dynamodb.us-east-1.amazonaws.com/"
Traceback (most recent call last):
  File "/usr/local/lib/python3.7/site-packages/urllib3/connection.py", line 159, in _new_conn
    (self._dns_host, self.port), self.timeout, **extra_kw)
  File "/usr/local/lib/python3.7/site-packages/urllib3/util/connection.py", line 57, in create_connection
    for res in socket.getaddrinfo(host, port, family, socket.SOCK_STREAM):
  File "/usr/local/Cellar/python/3.7.3/Frameworks/Python.framework/Versions/3.7/lib/python3.7/socket.py", line 748, in getaddrinfo
    for res in _socket.getaddrinfo(host, port, family, type, proto, flags):
socket.gaierror: [Errno 8] nodename nor servname provided, or not known

During handling of the above exception, another exception occurred:

Traceback (most recent call last):
  File "/usr/local/lib/python3.7/site-packages/botocore/httpsession.py", line 262, in send
    chunked=self._chunked(request.headers),
  File "/usr/local/lib/python3.7/site-packages/urllib3/connectionpool.py", line 638, in urlopen
    _stacktrace=sys.exc_info()[2])
  File "/usr/local/lib/python3.7/site-packages/urllib3/util/retry.py", line 343, in increment
    raise six.reraise(type(error), error, _stacktrace)
  File "/usr/local/lib/python3.7/site-packages/urllib3/packages/six.py", line 686, in reraise
    raise value
  File "/usr/local/lib/python3.7/site-packages/urllib3/connectionpool.py", line 600, in urlopen
    chunked=chunked)
  File "/usr/local/lib/python3.7/site-packages/urllib3/connectionpool.py", line 343, in _make_request
    self._validate_conn(conn)
  File "/usr/local/lib/python3.7/site-packages/urllib3/connectionpool.py", line 839, in _validate_conn
    conn.connect()
  File "/usr/local/lib/python3.7/site-packages/urllib3/connection.py", line 301, in connect
    conn = self._new_conn()
  File "/usr/local/lib/python3.7/site-packages/urllib3/connection.py", line 168, in _new_conn
    self, "Failed to establish a new connection: %s" % e)
urllib3.exceptions.NewConnectionError: <botocore.awsrequest.AWSHTTPSConnection object at 0x10856b0f0>: Failed to establish a new connection: [Errno 8] nodename nor servname provided, or not known

During handling of the above exception, another exception occurred:

Traceback (most recent call last):
  File "/usr/local/lib/python3.7/site-packages/botocore/retryhandler.py", line 269, in _should_retry
    return self._checker(attempt_number, response, caught_exception)
  File "/usr/local/lib/python3.7/site-packages/botocore/retryhandler.py", line 317, in __call__
    caught_exception)
  File "/usr/local/lib/python3.7/site-packages/botocore/retryhandler.py", line 223, in __call__
    attempt_number, caught_exception)
  File "/usr/local/lib/python3.7/site-packages/botocore/retryhandler.py", line 359, in _check_caught_exception
    raise caught_exception
  File "/usr/local/lib/python3.7/site-packages/botocore/endpoint.py", line 200, in _do_get_response
    http_response = self._send(request)
  File "/usr/local/lib/python3.7/site-packages/botocore/endpoint.py", line 244, in _send
    return self.http_session.send(request)
  File "/usr/local/lib/python3.7/site-packages/botocore/httpsession.py", line 282, in send
    raise EndpointConnectionError(endpoint_url=request.url, error=e)
botocore.exceptions.EndpointConnectionError: Could not connect to the endpoint URL: "https://dynamodb.us-east-1.amazonaws.com/"
DEBUG    botocore.retryhandler:retryhandler.py:185 Retry needed, action of: 3.2
DEBUG    botocore.endpoint:endpoint.py:239 Response received to retry, sleeping for 3.2 seconds
DEBUG    botocore.hooks:hooks.py:210 Event request-created.dynamodb.PutItem: calling handler <bound method RequestSigner.handler of <botocore.signers.RequestSigner object at 0x108449240>>
DEBUG    botocore.hooks:hooks.py:210 Event choose-signer.dynamodb.PutItem: calling handler <function set_operation_specific_signer at 0x1076ffae8>
DEBUG    botocore.auth:auth.py:364 Calculating signature using v4 auth.
DEBUG    botocore.auth:auth.py:365 CanonicalRequest:
POST
/

content-type:application/x-amz-json-1.0
host:dynamodb.us-east-1.amazonaws.com
x-amz-date:20190904T164915Z
x-amz-target:DynamoDB_20120810.PutItem

content-type;host;x-amz-date;x-amz-target
f7e44a43d150c8527b020229e6080c6a2fec4e99d61525c9cbee1289cc820b7a
DEBUG    botocore.auth:auth.py:367 StringToSign:
AWS4-HMAC-SHA256
20190904T164915Z
20190904/us-east-1/dynamodb/aws4_request
6116b28a9cb74bc246777defe674784e018eecc60f0ee24ff6e105a3ec5bfcdc
DEBUG    botocore.auth:auth.py:369 Signature:
969e05959b75d07ff3a91a34792459027e926f69f2fc7bca1d085af0bfe24f32
DEBUG    botocore.endpoint:endpoint.py:187 Sending http request: <AWSPreparedRequest stream_output=False, method=POST, url=https://dynamodb.us-east-1.amazonaws.com/, headers={'X-Amz-Target': b'DynamoDB_20120810.PutItem', 'Content-Type': b'application/x-amz-json-1.0', 'User-Agent': b'Boto3/1.9.213 Python/3.7.3 Darwin/18.6.0 Botocore/1.12.213', 'X-Amz-Date': b'20190904T164915Z', 'Authorization': b'AWS4-HMAC-SHA256 Credential=AKIAIOLQ5TSPFGTYHRIA/20190904/us-east-1/dynamodb/aws4_request, SignedHeaders=content-type;host;x-amz-date;x-amz-target, Signature=969e05959b75d07ff3a91a34792459027e926f69f2fc7bca1d085af0bfe24f32', 'Content-Length': '303'}>
DEBUG    urllib3.util.retry:retry.py:210 Converted retries value: False -> Retry(total=False, connect=None, read=None, redirect=0, status=None)
DEBUG    urllib3.connectionpool:connectionpool.py:813 Starting new HTTPS connection (8): dynamodb.us-east-1.amazonaws.com:443
DEBUG    botocore.endpoint:endpoint.py:205 Exception received when sending HTTP request.
Traceback (most recent call last):
  File "/usr/local/lib/python3.7/site-packages/urllib3/connection.py", line 159, in _new_conn
    (self._dns_host, self.port), self.timeout, **extra_kw)
  File "/usr/local/lib/python3.7/site-packages/urllib3/util/connection.py", line 57, in create_connection
    for res in socket.getaddrinfo(host, port, family, socket.SOCK_STREAM):
  File "/usr/local/Cellar/python/3.7.3/Frameworks/Python.framework/Versions/3.7/lib/python3.7/socket.py", line 748, in getaddrinfo
    for res in _socket.getaddrinfo(host, port, family, type, proto, flags):
socket.gaierror: [Errno 8] nodename nor servname provided, or not known

During handling of the above exception, another exception occurred:

Traceback (most recent call last):
  File "/usr/local/lib/python3.7/site-packages/botocore/httpsession.py", line 262, in send
    chunked=self._chunked(request.headers),
  File "/usr/local/lib/python3.7/site-packages/urllib3/connectionpool.py", line 638, in urlopen
    _stacktrace=sys.exc_info()[2])
  File "/usr/local/lib/python3.7/site-packages/urllib3/util/retry.py", line 343, in increment
    raise six.reraise(type(error), error, _stacktrace)
  File "/usr/local/lib/python3.7/site-packages/urllib3/packages/six.py", line 686, in reraise
    raise value
  File "/usr/local/lib/python3.7/site-packages/urllib3/connectionpool.py", line 600, in urlopen
    chunked=chunked)
  File "/usr/local/lib/python3.7/site-packages/urllib3/connectionpool.py", line 343, in _make_request
    self._validate_conn(conn)
  File "/usr/local/lib/python3.7/site-packages/urllib3/connectionpool.py", line 839, in _validate_conn
    conn.connect()
  File "/usr/local/lib/python3.7/site-packages/urllib3/connection.py", line 301, in connect
    conn = self._new_conn()
  File "/usr/local/lib/python3.7/site-packages/urllib3/connection.py", line 168, in _new_conn
    self, "Failed to establish a new connection: %s" % e)
urllib3.exceptions.NewConnectionError: <botocore.awsrequest.AWSHTTPSConnection object at 0x10856bba8>: Failed to establish a new connection: [Errno 8] nodename nor servname provided, or not known

During handling of the above exception, another exception occurred:

Traceback (most recent call last):
  File "/usr/local/lib/python3.7/site-packages/botocore/endpoint.py", line 200, in _do_get_response
    http_response = self._send(request)
  File "/usr/local/lib/python3.7/site-packages/botocore/endpoint.py", line 244, in _send
    return self.http_session.send(request)
  File "/usr/local/lib/python3.7/site-packages/botocore/httpsession.py", line 282, in send
    raise EndpointConnectionError(endpoint_url=request.url, error=e)
botocore.exceptions.EndpointConnectionError: Could not connect to the endpoint URL: "https://dynamodb.us-east-1.amazonaws.com/"
DEBUG    botocore.hooks:hooks.py:210 Event needs-retry.dynamodb.PutItem: calling handler <botocore.retryhandler.RetryHandler object at 0x108449630>
DEBUG    botocore.retryhandler:retryhandler.py:272 retry needed, retryable exception caught: Could not connect to the endpoint URL: "https://dynamodb.us-east-1.amazonaws.com/"
Traceback (most recent call last):
  File "/usr/local/lib/python3.7/site-packages/urllib3/connection.py", line 159, in _new_conn
    (self._dns_host, self.port), self.timeout, **extra_kw)
  File "/usr/local/lib/python3.7/site-packages/urllib3/util/connection.py", line 57, in create_connection
    for res in socket.getaddrinfo(host, port, family, socket.SOCK_STREAM):
  File "/usr/local/Cellar/python/3.7.3/Frameworks/Python.framework/Versions/3.7/lib/python3.7/socket.py", line 748, in getaddrinfo
    for res in _socket.getaddrinfo(host, port, family, type, proto, flags):
socket.gaierror: [Errno 8] nodename nor servname provided, or not known

During handling of the above exception, another exception occurred:

Traceback (most recent call last):
  File "/usr/local/lib/python3.7/site-packages/botocore/httpsession.py", line 262, in send
    chunked=self._chunked(request.headers),
  File "/usr/local/lib/python3.7/site-packages/urllib3/connectionpool.py", line 638, in urlopen
    _stacktrace=sys.exc_info()[2])
  File "/usr/local/lib/python3.7/site-packages/urllib3/util/retry.py", line 343, in increment
    raise six.reraise(type(error), error, _stacktrace)
  File "/usr/local/lib/python3.7/site-packages/urllib3/packages/six.py", line 686, in reraise
    raise value
  File "/usr/local/lib/python3.7/site-packages/urllib3/connectionpool.py", line 600, in urlopen
    chunked=chunked)
  File "/usr/local/lib/python3.7/site-packages/urllib3/connectionpool.py", line 343, in _make_request
    self._validate_conn(conn)
  File "/usr/local/lib/python3.7/site-packages/urllib3/connectionpool.py", line 839, in _validate_conn
    conn.connect()
  File "/usr/local/lib/python3.7/site-packages/urllib3/connection.py", line 301, in connect
    conn = self._new_conn()
  File "/usr/local/lib/python3.7/site-packages/urllib3/connection.py", line 168, in _new_conn
    self, "Failed to establish a new connection: %s" % e)
urllib3.exceptions.NewConnectionError: <botocore.awsrequest.AWSHTTPSConnection object at 0x10856bba8>: Failed to establish a new connection: [Errno 8] nodename nor servname provided, or not known

During handling of the above exception, another exception occurred:

Traceback (most recent call last):
  File "/usr/local/lib/python3.7/site-packages/botocore/retryhandler.py", line 269, in _should_retry
    return self._checker(attempt_number, response, caught_exception)
  File "/usr/local/lib/python3.7/site-packages/botocore/retryhandler.py", line 317, in __call__
    caught_exception)
  File "/usr/local/lib/python3.7/site-packages/botocore/retryhandler.py", line 223, in __call__
    attempt_number, caught_exception)
  File "/usr/local/lib/python3.7/site-packages/botocore/retryhandler.py", line 359, in _check_caught_exception
    raise caught_exception
  File "/usr/local/lib/python3.7/site-packages/botocore/endpoint.py", line 200, in _do_get_response
    http_response = self._send(request)
  File "/usr/local/lib/python3.7/site-packages/botocore/endpoint.py", line 244, in _send
    return self.http_session.send(request)
  File "/usr/local/lib/python3.7/site-packages/botocore/httpsession.py", line 282, in send
    raise EndpointConnectionError(endpoint_url=request.url, error=e)
botocore.exceptions.EndpointConnectionError: Could not connect to the endpoint URL: "https://dynamodb.us-east-1.amazonaws.com/"
DEBUG    botocore.retryhandler:retryhandler.py:185 Retry needed, action of: 6.4
DEBUG    botocore.endpoint:endpoint.py:239 Response received to retry, sleeping for 6.4 seconds
DEBUG    botocore.hooks:hooks.py:210 Event request-created.dynamodb.PutItem: calling handler <bound method RequestSigner.handler of <botocore.signers.RequestSigner object at 0x108449240>>
DEBUG    botocore.hooks:hooks.py:210 Event choose-signer.dynamodb.PutItem: calling handler <function set_operation_specific_signer at 0x1076ffae8>
DEBUG    botocore.auth:auth.py:364 Calculating signature using v4 auth.
DEBUG    botocore.auth:auth.py:365 CanonicalRequest:
POST
/

content-type:application/x-amz-json-1.0
host:dynamodb.us-east-1.amazonaws.com
x-amz-date:20190904T164922Z
x-amz-target:DynamoDB_20120810.PutItem

content-type;host;x-amz-date;x-amz-target
f7e44a43d150c8527b020229e6080c6a2fec4e99d61525c9cbee1289cc820b7a
DEBUG    botocore.auth:auth.py:367 StringToSign:
AWS4-HMAC-SHA256
20190904T164922Z
20190904/us-east-1/dynamodb/aws4_request
4a98e517fb7efba8c19fd9cb2bab002ca6f973727d307e4bbfed6a6857953f8f
DEBUG    botocore.auth:auth.py:369 Signature:
8fa8a62ae05bfa4aad7339a7b2cb05429df9071cd83d33e4d44e5c9959e99567
DEBUG    botocore.endpoint:endpoint.py:187 Sending http request: <AWSPreparedRequest stream_output=False, method=POST, url=https://dynamodb.us-east-1.amazonaws.com/, headers={'X-Amz-Target': b'DynamoDB_20120810.PutItem', 'Content-Type': b'application/x-amz-json-1.0', 'User-Agent': b'Boto3/1.9.213 Python/3.7.3 Darwin/18.6.0 Botocore/1.12.213', 'X-Amz-Date': b'20190904T164922Z', 'Authorization': b'AWS4-HMAC-SHA256 Credential=AKIAIOLQ5TSPFGTYHRIA/20190904/us-east-1/dynamodb/aws4_request, SignedHeaders=content-type;host;x-amz-date;x-amz-target, Signature=8fa8a62ae05bfa4aad7339a7b2cb05429df9071cd83d33e4d44e5c9959e99567', 'Content-Length': '303'}>
DEBUG    urllib3.util.retry:retry.py:210 Converted retries value: False -> Retry(total=False, connect=None, read=None, redirect=0, status=None)
DEBUG    urllib3.connectionpool:connectionpool.py:813 Starting new HTTPS connection (9): dynamodb.us-east-1.amazonaws.com:443
DEBUG    botocore.endpoint:endpoint.py:205 Exception received when sending HTTP request.
Traceback (most recent call last):
  File "/usr/local/lib/python3.7/site-packages/urllib3/connection.py", line 159, in _new_conn
    (self._dns_host, self.port), self.timeout, **extra_kw)
  File "/usr/local/lib/python3.7/site-packages/urllib3/util/connection.py", line 57, in create_connection
    for res in socket.getaddrinfo(host, port, family, socket.SOCK_STREAM):
  File "/usr/local/Cellar/python/3.7.3/Frameworks/Python.framework/Versions/3.7/lib/python3.7/socket.py", line 748, in getaddrinfo
    for res in _socket.getaddrinfo(host, port, family, type, proto, flags):
socket.gaierror: [Errno 8] nodename nor servname provided, or not known

During handling of the above exception, another exception occurred:

Traceback (most recent call last):
  File "/usr/local/lib/python3.7/site-packages/botocore/httpsession.py", line 262, in send
    chunked=self._chunked(request.headers),
  File "/usr/local/lib/python3.7/site-packages/urllib3/connectionpool.py", line 638, in urlopen
    _stacktrace=sys.exc_info()[2])
  File "/usr/local/lib/python3.7/site-packages/urllib3/util/retry.py", line 343, in increment
    raise six.reraise(type(error), error, _stacktrace)
  File "/usr/local/lib/python3.7/site-packages/urllib3/packages/six.py", line 686, in reraise
    raise value
  File "/usr/local/lib/python3.7/site-packages/urllib3/connectionpool.py", line 600, in urlopen
    chunked=chunked)
  File "/usr/local/lib/python3.7/site-packages/urllib3/connectionpool.py", line 343, in _make_request
    self._validate_conn(conn)
  File "/usr/local/lib/python3.7/site-packages/urllib3/connectionpool.py", line 839, in _validate_conn
    conn.connect()
  File "/usr/local/lib/python3.7/site-packages/urllib3/connection.py", line 301, in connect
    conn = self._new_conn()
  File "/usr/local/lib/python3.7/site-packages/urllib3/connection.py", line 168, in _new_conn
    self, "Failed to establish a new connection: %s" % e)
urllib3.exceptions.NewConnectionError: <botocore.awsrequest.AWSHTTPSConnection object at 0x10857a6a0>: Failed to establish a new connection: [Errno 8] nodename nor servname provided, or not known

During handling of the above exception, another exception occurred:

Traceback (most recent call last):
  File "/usr/local/lib/python3.7/site-packages/botocore/endpoint.py", line 200, in _do_get_response
    http_response = self._send(request)
  File "/usr/local/lib/python3.7/site-packages/botocore/endpoint.py", line 244, in _send
    return self.http_session.send(request)
  File "/usr/local/lib/python3.7/site-packages/botocore/httpsession.py", line 282, in send
    raise EndpointConnectionError(endpoint_url=request.url, error=e)
botocore.exceptions.EndpointConnectionError: Could not connect to the endpoint URL: "https://dynamodb.us-east-1.amazonaws.com/"
DEBUG    botocore.hooks:hooks.py:210 Event needs-retry.dynamodb.PutItem: calling handler <botocore.retryhandler.RetryHandler object at 0x108449630>
DEBUG    botocore.retryhandler:retryhandler.py:272 retry needed, retryable exception caught: Could not connect to the endpoint URL: "https://dynamodb.us-east-1.amazonaws.com/"
Traceback (most recent call last):
  File "/usr/local/lib/python3.7/site-packages/urllib3/connection.py", line 159, in _new_conn
    (self._dns_host, self.port), self.timeout, **extra_kw)
  File "/usr/local/lib/python3.7/site-packages/urllib3/util/connection.py", line 57, in create_connection
    for res in socket.getaddrinfo(host, port, family, socket.SOCK_STREAM):
  File "/usr/local/Cellar/python/3.7.3/Frameworks/Python.framework/Versions/3.7/lib/python3.7/socket.py", line 748, in getaddrinfo
    for res in _socket.getaddrinfo(host, port, family, type, proto, flags):
socket.gaierror: [Errno 8] nodename nor servname provided, or not known

During handling of the above exception, another exception occurred:

Traceback (most recent call last):
  File "/usr/local/lib/python3.7/site-packages/botocore/httpsession.py", line 262, in send
    chunked=self._chunked(request.headers),
  File "/usr/local/lib/python3.7/site-packages/urllib3/connectionpool.py", line 638, in urlopen
    _stacktrace=sys.exc_info()[2])
  File "/usr/local/lib/python3.7/site-packages/urllib3/util/retry.py", line 343, in increment
    raise six.reraise(type(error), error, _stacktrace)
  File "/usr/local/lib/python3.7/site-packages/urllib3/packages/six.py", line 686, in reraise
    raise value
  File "/usr/local/lib/python3.7/site-packages/urllib3/connectionpool.py", line 600, in urlopen
    chunked=chunked)
  File "/usr/local/lib/python3.7/site-packages/urllib3/connectionpool.py", line 343, in _make_request
    self._validate_conn(conn)
  File "/usr/local/lib/python3.7/site-packages/urllib3/connectionpool.py", line 839, in _validate_conn
    conn.connect()
  File "/usr/local/lib/python3.7/site-packages/urllib3/connection.py", line 301, in connect
    conn = self._new_conn()
  File "/usr/local/lib/python3.7/site-packages/urllib3/connection.py", line 168, in _new_conn
    self, "Failed to establish a new connection: %s" % e)
urllib3.exceptions.NewConnectionError: <botocore.awsrequest.AWSHTTPSConnection object at 0x10857a6a0>: Failed to establish a new connection: [Errno 8] nodename nor servname provided, or not known

During handling of the above exception, another exception occurred:

Traceback (most recent call last):
  File "/usr/local/lib/python3.7/site-packages/botocore/retryhandler.py", line 269, in _should_retry
    return self._checker(attempt_number, response, caught_exception)
  File "/usr/local/lib/python3.7/site-packages/botocore/retryhandler.py", line 317, in __call__
    caught_exception)
  File "/usr/local/lib/python3.7/site-packages/botocore/retryhandler.py", line 223, in __call__
    attempt_number, caught_exception)
  File "/usr/local/lib/python3.7/site-packages/botocore/retryhandler.py", line 359, in _check_caught_exception
    raise caught_exception
  File "/usr/local/lib/python3.7/site-packages/botocore/endpoint.py", line 200, in _do_get_response
    http_response = self._send(request)
  File "/usr/local/lib/python3.7/site-packages/botocore/endpoint.py", line 244, in _send
    return self.http_session.send(request)
  File "/usr/local/lib/python3.7/site-packages/botocore/httpsession.py", line 282, in send
    raise EndpointConnectionError(endpoint_url=request.url, error=e)
botocore.exceptions.EndpointConnectionError: Could not connect to the endpoint URL: "https://dynamodb.us-east-1.amazonaws.com/"
DEBUG    botocore.retryhandler:retryhandler.py:185 Retry needed, action of: 12.8
DEBUG    botocore.endpoint:endpoint.py:239 Response received to retry, sleeping for 12.8 seconds
